Workbook

Sheet Fiche de suivi 2025
C1: Tableau de suivi des dossiers - Laboratoire Performance Energétique des lave - linge / Année 2025
A2: TOTAL Offre de prix : | E2: =SUM(T12:T80) -> 181100 | W2: Durée moyenne d'éxécution des essais | X2: Durée moyenne de traitement de dossier | Z2: Nbr de dossiers : | AB2: =MAX(A12:A131) -> 44
A3: Facturation : | C3: Capacité : | E3: =U36+U46+U47+U49 -> 4200 | G3: =E3/$E$7 -> 0.026282854 | Z3: Nbr d'appareil : | AB3: =MAX(B12:B161) -> 73
C4: Constat / autre : | E4: =U15+U19+U34+U37+U39+U41+U44+U43+U52+U68+U64+U67+U77+U81 -> 15600 | G4: =E4/$E$7 -> 0.097622028 | T4: =T5/160000 -> 1.131875 | V4: reste a payé
C5: Labo client : | G5: =E5/$E$7 -> 0 | T5: =SUM(T12:T80) -> 181100 | U5: =SUM(U12:U80) -> 159200 | V5: =T5-U5 -> 21900
C6: Labo CETIME : | E6: =U12+U14+U16+U17+U24+U23+U22+U29+U30+U31+U35+U38+U42+U45+U51+U54+U61+U57+U63+U79 -> 135000 | G6: =E6/$E$7 -> 0.84480601 | K6: =SUM(K12:K100) -> 15 | L6: =SUM(L12:L234) -> 0 | N6: =SUM(N12:N100) -> 7 | O6: =SUM(O12:O100) -> 11 | P6: =SUM(P12:P100) -> 30 | Q6: =SUM(Q12:Q100) -> 54 | R6: =SUM(R12:R100) -> 6 | S6: =SUM(S12:S100) -> 7 | V6: =V5/E2 -> 0.12092766 | W6: =AVERAGE(W12:W46) -> 15.966667 | X6: =AVERAGE(X12:X46) -> 26.545455 | AG6: Respect des délais
C7: Total : | E7: =E3+E4+E5+E6+U26 -> 159800 | G7: =E7/E2 -> 0.88238542 | W7: =MAX(W12:W46) -> 37 | X7: =MAX(X12:X46) -> 70 | AG7: =SUM(AG12:AG100) -> 40 | AJ7: Délais reception / confirmation
W8: =MIN(W12:W46) -> 1 | X8: =MIN(X12:X46) -> 1
A9: N° | C9: Code Projet | E9: Client | F9: Marque | G9: Modèle | H9: Kg | I9: Type de l'essai | J9: Réception échantillons | N9: En cours | P9: Achevés | R9: Confirmation | T9: Offre de prix | U9: Facturation | W9: Délai de réalisation / essai (jours) | X9: Délai de traitement de dossier (jours) | Z9: Rapport d'essai
Z10: Date
J11: Date | K11: Récep | L11: Stock | M11: Etat | T11: Montant HT | U11: Montant HT | V11: Date
A12: 1 | B12: 1 | C12: A373 | D12: A373251 | E12: ELECTRO SERVICE | F12: TELEFUNKEN | G12: TL0914T3DG | H12: 9 | I12: Classification | J12: 45663 | M12: Rendu | P12: 1 | Q12: 1 | T12: 9500 | U12: 9500 | V12: 45665 | W12: =Z12-(MAX(V12,J12)) -> 13 | X12: =Z12-J12 -> 15 | Y12: =IF(W12<21,"Dans les délais","Hors délais") -> Dans les délais | Z12: 45678 | AG12: =IF(Y12="dans les délais",1,0) -> 1 | AJ12: =V12-J12 -> 2
B13: 2 | C13: A373 | D13: A373251 | F13: TELEFUNKEN | G13: TL1014T3DG | H13: 10 | I13: Classification | J13: 45663 | M13: Rendu | Q13: 1 | V13: 45665 | W13: =Z13-(MAX(V13,J13)) -> 13 | Y13: =IF(W13<30,"Dans les délais","Hors délais") -> Dans les délais | Z13: 45678 | AG13: =IF(Y13="dans les délais",1,0) -> 1 | AJ13: =V13-J13 -> 2
A14: 2 | B14: 3 | C14: A373 | D14: A373252 | E14: DELTA TRADING | F14: NEWSTAR | G14: MFA1214 | H14: 12 | I14: Classification | J14: 45666 | M14: Rendu | P14: 1 | Q14: 1 | T14: 5000 | U14: 5000 | V14: 45673 | W14: =Z14-(MAX(V14,J14)) -> 5 | X14: =Z14-J14 -> 12 | Y14: =IF(W14<30,"Dans les délais","Hors délais") -> Dans les délais | Z14: 45678 | AG14: =IF(Y14="dans les délais",1,0) -> 1 | AJ14: =V14-J14 -> 7
A15: 3 | B15: 4 | C15: A373 | D15: A373253 | E15: GAN Distribution | F15: Mont blanc | G15: BU1050 | H15: 7 | I15: Constat | J15: 45666 | M15: Rendu | P15: 1 | Q15: 1 | T15: 600 | U15: 600 | V15: 45678 | W15: =Z15-(MAX(V15,J15)) -> 21 | X15: =Z15-J15 -> 33 | Y15: =IF(W15<15,"Dans les délais","Hors délais") -> Hors délais | Z15: 45699 | AG15: =IF(Y15="dans les délais",1,0) -> 0 | AJ15: =V15-J15 -> 12
A16: 4 | B16: 5 | C16: A371 | D16: A373251 | E16: El Athir Service | F16: TCL | G16: P606FLW | H16: 6 | I16: Classification | J16: 45663 | M16: Rendu | P16: 1 | Q16: 1 | T16: 5000 | U16: 5000 | V16: 45667 | W16: =Z16-(MAX(V16,J16)) -> 25 | X16: =Z16-J16 -> 29 | Y16: =IF(W16<30,"Dans les délais","Hors délais") -> Dans les délais | Z16: 45692 | AG16: =IF(Y16="dans les délais",1,0) -> 1 | AJ16: =V16-J16 -> 4
A17: 5 | B17: 6 | C17: A373 | D17: A373254 | E17: Brandt Tunisie | F17: Brandt | G17: BLF942QSBL | H17: 9 | I17: Classification | J17: 45672 | M17: Rendu | P17: 1 | Q17: 1 | T17: 11300 | U17: 9500 | V17: 45691 | W17: =Z17-(MAX(V17,J17)) -> 37 | X17: =Z17-J17 -> 56 | Y17: =IF(W17<30,"Dans les délais","Hors délais") -> Hors délais | Z17: 45728 | AG17: =IF(Y17="dans les délais",1,0) -> 0 | AJ17: =V17-J17 -> 19
B18: 7 | C18: A373 | D18: A373254 | F18: Brandt | G18: BAM1052SBL | H18: 10 | I18: Classification | J18: 45672 | M18: Rendu | Q18: 1 | V18: 45691 | W18: =Z18-(MAX(V18,J18)) -> 24 | Y18: =IF(W18<30,"Dans les délais","Hors délais") -> Dans les délais | Z18: 45715 | AG18: =IF(Y18="dans les délais",1,0) -> 1 | AJ18: =V18-J18 -> 19
B19: 8 | C19: A373 | D19: A373254 | F19: Brandt | G19: BLF742S | H19: 7 | I19: Constat | J19: 45672 | M19: Rendu | Q19: 1 | U19: 1800 | V19: 45691 | W19: =Z19-(MAX(V19,J19)) -> 8 | Y19: =IF(W19<30,"Dans les délais","Hors délais") -> Dans les délais | Z19: 45699 | AG19: =IF(Y19="dans les délais",1,0) -> 1 | AJ19: =V19-J19 -> 19
B20: 9 | C20: A373 | D20: A373254 | F20: Brandt | G20: BAM84SBL | H20: 8 | I20: Constat | J20: 45672 | M20: Rendu | Q20: 1 | V20: 45691 | W20: =Z20-(MAX(V20,J20)) -> 8 | Y20: =IF(W20<30,"Dans les délais","Hors délais") -> Dans les délais | Z20: 45699 | AG20: =IF(Y20="dans les délais",1,0) -> 1 | AJ20: =V20-J20 -> 19
B21: 10 | C21: A373 | D21: A373254 | F21: Brandt | G21: BAM1052WBL | H21: 10 | I21: Constat | J21: 45672 | M21: Rendu | Q21: 1 | V21: 45691 | W21: =Z21-(MAX(V21,J21)) -> 24 | Y21: =IF(W21<30,"Dans les délais","Hors délais") -> Dans les délais | Z21: 45715 | AG21: =IF(Y21="dans les délais",1,0) -> 1 | AJ21: =V21-J21 -> 19
A22: 6 | B22: 11 | C22: A371 | D22: A371253 | E22: ELECTRO SERVICE | F22: TELEFUNKEN | G22: TL0610T0W | H22: 6 | I22: Classification | J22: 45687 | M22: Rendu | P22: 1 | Q22: 1 | T22: 5000 | U22: 5000 | V22: 45709 | W22: =Z22-(MAX(V22,J22)) -> 6 | X22: =Z22-J22 -> 28 | Y22: =IF(W22<30,"Dans les délais","Hors délais") -> Dans les délais | Z22: 45715 | AG22: =IF(Y22="dans les délais",1,0) -> 1 | AJ22: =V22-J22 -> 22
A23: 7 | B23: 12 | C23: A371 | D23: A371256 | E23: CONDOR ELECTRONICS INTERNATIONAL | F23: Condor | G23: WF6-A12 | H23: 6 | I23: Classification | J23: 45692 | M23: Rendu | P23: 1 | Q23: 1 | T23: 4000 | U23: 4000 | V23: 45701 | W23: =Z23-(MAX(V23,J23)) -> 36 | X23: =Z23-J23 -> 45 | Y23: =IF(W23<30,"Dans les délais","Hors délais") -> Hors délais | Z23: 45737 | AG23: =IF(Y23="dans les délais",1,0) -> 0 | AJ23: =V23-J23 -> 9
A24: 8 | B24: 13 | C24: A373 | D24: A373255 | E24: NEWSTAR | F24: NEWSTAR | G24: MFA0810 | H24: 8 | I24: Classification | J24: 45687 | M24: Rendu | P24: 1 | Q24: 1 | T24: 9500 | U24: 9500 | V24: 45695 | W24: =Z24-(MAX(V24,J24)) -> 27 | X24: =Z25-J25 -> 40 | Y24: =IF(W24<30,"Dans les délais","Hors délais") -> Dans les délais | Z24: 45722 | AG24: =IF(Y24="dans les délais",1,0) -> 1 | AJ24: =V24-J24 -> 8
B25: 14 | C25: A373 | D25: A373255 | F25: NEWSTAR | G25: MFA0910 | H25: 9 | I25: Classification | J25: 45687 | M25: Rendu | Q25: 1 | V25: 45695 | W25: =Z25-(MAX(V25,J25)) -> 32 | Y25: =IF(W25<30,"Dans les délais","Hors délais") -> Hors délais | Z25: 45727 | AG25: =IF(Y25="dans les délais",1,0) -> 0 | AJ25: =V25-J25 -> 8
A26: 9 | B26: 15 | C26: A373 | D26: A373257 | E26: MONDIAL CONFORT | F26: Beko | G26: B3WFT51242MG | H26: 12 | I26: Classification | J26: 45692 | M26: Rendu | P26: 1 | Q26: 1 | T26: 5000 | U26: 5000 | V26: 45698 | W26: =Z26-(MAX(V26,J26)) -> 10 | X26: =Z26-J26 -> 16 | Y26: =IF(W26<30,"Dans les délais","Hors délais") -> Dans les délais | Z26: 45708 | AG26: =IF(Y26="dans les délais",1,0) -> 1 | AJ26: =V26-J26 -> 6
A27: 10 | B27: 16 | C27: A373 | D27: A373258 | E27: CROCUS COMPANY TRAIDING | F27: AZUR | G27: AZ1210T2T | H27: 12 | I27: Classification | J27: 45701 | M27: Rendu / sans essai | P27: 1 | Q27: 1 | T27: 5000 | U27: 0 | AG27: =IF(Y27="dans les délais",1,0) -> 0
A28: 11 | B28: 17 | C28: A371 | D28: A371257 | E28: CROCUS COMPANY TRAIDING | F28: AZUR | I28: Classification | J28: 45701 | K28: 1 | M28: reçu | R28: 1 | S28: 1 | T28: 5000 | AG28: =IF(Y28="dans les délais",1,0) -> 0
A29: 12 | B29: 18 | C29: A373 | D29: A373259 | E29: El Athir Service | F29: CANDY | G29: RO1411DMCRT | H29: 11 | I29: Classification | J29: 45702 | M29: Rendu | P29: 1 | Q29: 1 | T29: 5000 | U29: 5000 | V29: 45728 | W29: =Z29-(MAX(V29,J29)) -> 21 | X29: =Z29-J29 -> 47 | Y29: =IF(W29<30,"Dans les délais","Hors délais") -> Dans les délais | Z29: 45749 | AG29: =IF(Y29="dans les délais",1,0) -> 1 | AJ29: =V29-J29 -> 26
A30: 13 | B30: 19 | C30: A371 | D30: A371258 | E30: CONDOR ELECTRONICS INTERNATIONAL | F30: Condor | G30: CON-G610S | H30: 6 | I30: Classification | J30: 45723 | M30: Rendu | P30: 1 | Q30: 1 | T30: 4000 | U30: 4000 | V30: 45734 | W30: =Z30-(MAX(V30,J30)) -> 21 | X30: =Z30-J30 -> 32 | Y30: =IF(W30<30,"Dans les délais","Hors délais") -> Dans les délais | Z30: 45755 | AG30: =IF(Y30="dans les délais",1,0) -> 1 | AJ30: =V30-J30 -> 11
A31: 14 | B31: 20 | C31: A373 | D31: A3732510 | E31: MONDIAL CONFORT | F31: Beko | G31: BM1WFU36200BW | H31: 6 | I31: Classification | J31: 45750 | M31: Rendu | P31: 1 | Q31: 1 | T31: 9500 | U31: 9500 | V31: 45757 | W31: =Z31-(MAX(V31,J31)) -> 14 | X31: =Z31-J31 -> 21 | Y31: =IF(W31<30,"Dans les délais","Hors délais") -> Dans les délais | Z31: 45771 | AG31: =IF(Y31="dans les délais",1,0) -> 1 | AJ31: =V31-J31 -> 7
B32: 21 | C32: A373 | D32: A3732510 | F32: Beko | G32: BM3WFU47200BS | H32: 7 | I32: Classification | J32: 45750 | M32: Rendu | Q32: 1 | V32: 45757 | W32: =Z32-(MAX(V32,J32)) -> 13 | Y32: =IF(W32<30,"Dans les délais","Hors délais") -> Dans les délais | Z32: 45770 | AG32: =IF(Y32="dans les délais",1,0) -> 1 | AJ32: =V32-J32 -> 7
B33: 22 | C33: A373 | D33: A3732510 | F33: Beko | G33: B3WFU4822MG | H33: 8 | I33: Constat | J33: 45750 | M33: Rendu | Q33: 1 | V33: 45757 | W33: =Z33-(MAX(V33,J33)) -> 11 | Y33: =IF(W33<30,"Dans les délais","Hors délais") -> Dans les délais | Z33: 45768 | AG33: =IF(Y33="dans les délais",1,0) -> 1 | AJ33: =V33-J33 -> 7
A34: 15 | B34: 23 | C34: A373 | D34: A3732513 | E34: Brandt Tunisie | F34: Brandt | G34: BLF842B | H34: 8 | I34: Constat | J34: 45761 | M34: Rendu | P34: 1 | Q34: 1 | T34: 600 | U34: 600 | V34: 45770 | W34: =Z34-(MAX(V34,J34)) -> 6 | X34: =Z34-J34 -> 15 | Y34: =IF(W34<30,"Dans les délais","Hors délais") -> Dans les délais | Z34: 45776 | AG34: =IF(Y34="dans les délais",1,0) -> 1 | AJ34: =V34-J34 -> 9
A35: 16 | B35: 24 | C35: A373 | D35: A3732514 | E35: El Athir Service | F35: SAMSUNG | G35: WD11DB7B85GB | H35: 11 | I35: Classification | J35: 45769 | M35: Rendu | P35: 1 | Q35: 1 | T35: 5000 | U35: 5000 | V35: 45784 | W35: =Z35-(MAX(V35,J35)) -> 29 | X35: =Z35-J35 -> 44 | Y35: =IF(W35<30,"Dans les délais","Hors délais") -> Dans les délais | Z35: 45813 | AG35: =IF(Y35="dans les délais",1,0) -> 1 | AJ35: =V35-J35 -> 15
A36: 17 | B36: 25 | C36: A373 | D36: A3732515 | E36: El Athir Service | F36: SAMSUNG | G36: WD11DB7B85GB | H36: 11 | I36: Capacité | J36: 45771 | M36: Rendu | P36: 1 | Q36: 1 | T36: 700 | U36: 700 | V36: 45771 | W36: =Z36-(MAX(V36,J36)) -> 1 | X36: =Z36-J36 -> 1 | Y36: =IF(W36<30,"Dans les délais","Hors délais") -> Dans les délais | Z36: 45772 | AG36: =IF(Y36="dans les délais",1,0) -> 1 | AJ36: =V36-J36 -> 0
A37: 18 | B37: 26 | C37: A371 | D37: A3712511 | E37: COFEM | F37: Orient | G37: OW-F5V01S | H37: 5 | I37: Constat | J37: 45772 | M37: Rendu | P37: 1 | Q37: 1 | T37: 600 | U37: 600 | V37: 45775 | W37: =Z37-(MAX(V37,J37)) -> 4 | X37: =Z37-J37 -> 7 | Y37: =IF(W37<30,"Dans les délais","Hors délais") -> Dans les délais | Z37: 45779 | AG37: =IF(Y37="dans les délais",1,0) -> 1 | AJ37: =V37-J37 -> 3
A38: 19 | B38: 27 | C38: A373 | D38: A3732516 | E38: MONDIAL CONFORT | F38: Beko | G38: BM3WFT48400BS | H38: 8 | I38: Classification | J38: 45777 | M38: Rendu | P38: 1 | Q38: 1 | T38: 5000 | U38: 5000 | V38: 45792 | W38: =Z38-(MAX(V38,J38)) -> 29 | X38: =Z38-J38 -> 44 | Y38: =IF(W38<30,"Dans les délais","Hors délais") -> Dans les délais | Z38: 45821 | AG38: =IF(Y38="dans les délais",1,0) -> 1 | AJ38: =V38-J38 -> 15
A39: 20 | B39: 28 | C39: A373 | D39: A3732517 | E39: CASAPRO | F39: HOOVER | G39: H3W 272 DGG-04 | H39: 7 | I39: Constat | J39: 45782 | M39: Rendu | P39: 1 | Q39: 1 | T39: 600 | U39: 600 | V39: 45785 | W39: =Z39-(MAX(V39,J39)) -> 1 | X39: =Z39-J39 -> 4 | Y39: =IF(W39<30,"Dans les délais","Hors délais") -> Dans les délais | Z39: 45786 | AG39: =IF(Y39="dans les délais",1,0) -> 1 | AJ39: =V39-J39 -> 3
A40: 21 | B40: 29 | C40: A373 | D40: A3732518 | E40: SMART HOME DISTRIBUTION | F40: Fresh | H40: 4 | I40: Capacité | J40: 45783 | M40: Annulé | P40: 1 | Q40: 1 | T40: 700 | AG40: =IF(Y40="dans les délais",1,0) -> 0
...

Sheet MV
E1: Direction Centrale des Laboratoires Electriques / D C L E
E2: Laboratoire de Performance Energétique des Laves - linge / Laboratoire P E L
E3: Tableau de bord / Mangement Visuel
A6: Réalisation & En cours 2025
P8: Planification sur 2 semaines
B10: Nombre Total | F10: ='Fiche de suivi 2025'!AB2 -> 44 | J10: ='Fiche de suivi 2025'!AB3 -> 73 | O10: Client | Q10: Marque / Modèle | S10: Kg | T10: Type d'essai | Y10: Nombre total | Z10: Nombre de demandes (essai + CT) reçus depuis le début de l'année 2025 / Nombre des échantillons réçus depuis le debut de l'année 2025
B11: Achvés : | F11: ='Fiche de suivi 2025'!P6 -> 30 | H11: =F11/F10 -> 0.68181818 | J11: ='Fiche de suivi 2025'!Q6 -> 54 | L11: =J11/J10 -> 0.73972603 | Y11: Achevés | Z11: Nombre de demandes (essai + CT) confirmés par le client et dont les essais ont étés achevés / Nombre des échantillons dont les essais ont étés achevés
B12: En cours de traitement : | F12: ='Fiche de suivi 2025'!N6 -> 7 | H12: =F12/F10 -> 0.15909091 | J12: ='Fiche de suivi 2025'!O6 -> 11 | L12: =J12/J10 -> 0.15068493 | Y12: En cours de traitement | Z12: Nombre de demandes (essai + CT) confirmés par le client et dont les essais sont en cours / Nombre des échantillons dont les essais sont en cours
B13: Attente confirmation : | F13: ='Fiche de suivi 2025'!R6 -> 6 | H13: =F13/F10 -> 0.13636364 | J13: ='Fiche de suivi 2025'!S6 -> 7 | L13: =J13/J10 -> 0.095890411 | Y13: Attente de confirmation | Z13: Nombre de demandes (essai + CT) dont les devis sont envoyés mais reste sans confirmation par le client
Y14: Durée moyenne d'éxécution des essais | Z14: Durée moyenne des essais sur un échantillon depuis la date de confirmation jusqu'au la date d'émission du rapport
D15: Durée moyenne de traitement de dossier | J15: Durée moyenne d'éxécution des essais | Z15: = Moyenne (Date d'émission du raport - Date de facturation)
Y16: Durée moyenne de traitement de dossier | Z16: Durée moyenne de traitement des dossiers depuis la date de réception de la demande et des échantillons jusqu'au la date d'émission du dernier rapport
D17: ='Fiche de suivi 2025'!X6 -> 26.545455 | F17: jours | J17: ='Fiche de suivi 2025'!W6 -> 15.966667 | L17: jours | N17: Respect des délais = | S17: ='Fiche de suivi 2025'!AG7/MV!J11 -> 0.74074074 | Z17: = Moyenne (Date d'émission du dernier raport - Date de réception de la demande)
Y18: Réception / En attente d'essai | Z18: Nombre d'échantillons actuellement reçu et en attente de confirmation client ou essai (dans la zone de réception)
A20: Stock & Espace | Z20: Espace occupé : espace occupé par les échantillons reçus à raison de 0,64 m² par échantillon (surface de la zonne 2 m²)
Y21: Stockage / Retour client | Z21: Nombre d'échantillons dont les essais sont achevés et en attente de récupération par le client (dans la zone de stockage)
D22: Réception / En attente d'essai | Q22: Stockage / Retour client
D23: =('Fiche de suivi 2025'!K6) -> 15 | E23: Appareils | G23: Espce occupé | Q23: ='Fiche de suivi 2025'!L6 -> 0 | R23: Appareils | T23: Espce occupé | Z23: Espace occupé : espace occupé par les échantillons en attente de récupération par le client à raison de 0,64 m² par échantillon (surface de la zonne 2 m²)
G24: =D23*0.64 -> 9.6 | H24: m² | I24: =G24/2 -> 4.8 | T24: =Q23*0.64 -> 0 | U24: m² | V24: =T24/2 -> 0 | Y24: Taux de respect des délais | Z24: Nombre des rapports dans les délais (30 jours par défaut) / nombre total des rapports
A26: Performance des Moyens d'essai (Equipements de laboratoire) | Y26: M T B F | Z26: Durée moyenne entre les pannes (arrêt non programmé)
Y27: M T T R | Z27: Durée moyenne de remise en état de fonctionnement après un arrêt non programmé
B28: Taux de disponibilité des moyens d'essais | J28: MTBF | M28: Arrêt programmé 2025 | P28: Taux de d'occupation des moyens d'essais
Y29: Arrêt programmé | Z29: Nombre de jours d'arrêt planifié à l'avance (étalonnage / maintenance préventive)
J30: Temps Moyen entre Pannes
Y31: Arrêt non programmé | Z31: Nombre de jours d'arrêt de fonctionnement accidentel du laboratoire suite à une panne
Y33: Taux de disponibilité des moyens d'essais | Z33: Représente le pourcentage de temps durant lequel les équipements du laboratoire sont opérationnels ((jours de travail - jours d'arrêt) / jours de travail)
J34: =Feuil2!D24 -> 400 | K34: jours | M34: =Feuil2!O5 -> 2 | N34: jours
Y36: Taux de d'occupation des moyens d'essais | Z36: Représente le pourcentage de jours d'utilisation des équipements du laboratoires ((jours de travail - jours d'utilisation) / jours de travail)
J38: MTTR | M38: Arrêt non programmé 2025
J40: Temps Moyen de Réparation
J44: =Feuil2!D25 -> 3 | K44: jours | M44: =Feuil2!G34 -> 0 | N44: jours

Sheet Feuil2
C3: Janvier | D3: Fevrier | E3: Mars | F3: Avril | G3: Mai | H3: Juin | I3: Juillet | J3: Août | K3: Septembre | L3: Octobre | M3: Novembre | N3: Décembre | O3: Somme / Moyenne
A4: 1 | B4: Jour de travail | C4: 22 | D4: 20 | E4: 19 | F4: 21 | G4: 21 | H4: 19 | I4: 22 | J4: 20 | K4: 21 | L4: 22 | M4: 20 | N4: 22 | O4: =SUM(C4:N4) -> 249
A5: 2 | B5: Arrêt programmé (Etalonnage / maintenance préventive) | C5: 0 | D5: 2 | E5: 0 | O5: =SUM(C5:N5) -> 2
B6: Arrêt non programmé (panne / défaut de foctionnement) | C6: 0 | D6: 0 | E6: 0 | O6: =SUM(C6:N6) -> 0
B7: Nombre de jours d'arrêt | C7: =SUM(C5:C6) -> 0 | D7: =SUM(D5:D6) -> 2 | E7: =SUM(E5:E6) -> 0 | F7: =SUM(F5:F6) -> 0 | G7: =SUM(G5:G6) -> 0 | H7: =SUM(H5:H6) -> 0 | I7: =SUM(I5:I6) -> 0 | J7: =SUM(J5:J6) -> 0 | ... N7: =SUM(N5:N6) -> 0
A8: 3 | B8: Taux de disponibilité des moyens d'essais | C8: =(C4-C7)/C4 -> 1 | D8: =(D4-D7)/D4 -> 0.9 | E8: =(E4-E7)/E4 -> 1 | F8: =(F4-F7)/F4 -> 1 | G8: =(G4-G7)/G4 -> 1 | H8: =(H4-H7)/H4 -> 1 | I8: =(I4-I7)/I4 -> 1 | J8: =(J4-J7)/J4 -> 1 | ... N8: =(N4-N7)/N4 -> 1 | O8: =AVERAGE(C8:D8) -> 0.95 | P8: =100%-O8 -> 0.05
A9: 4 | B9: Utilisation des moyens d'essai (jours) | C9: 14 | D9: 17 | E9: 5 | O9: =SUM(C9:N9) -> 36
B10: Taux d'occupation des moyens d'essai | C10: =C9/C4 -> 0.63636364 | D10: =D9/D4 -> 0.85 | E10: =E9/E4 -> 0.26315789 | F10: =F9/F4 -> 0 | G10: =G9/G4 -> 0 | H10: =H9/H4 -> 0 | I10: =I9/I4 -> 0 | J10: =J9/J4 -> 0 | ... N10: =N9/N4 -> 0 | O10: =AVERAGE(C10:D10) -> 0.74318182 | P10: =100%-O10 -> 0.25681818
G16: =45/47 -> 0.95744681
B24: Temps moyene entre pannes | C24: MTBF | D24: =C27-C26 -> 400 | E24: jours
B25: Temps Moyen de Réparation | C25: MTTR | D25: =AVERAGE(D30,D33,D36) -> 3 | E25: jours
B26: Date du dernier remise en état après un arrêt non programé | C26: 45509
B27: Aujourd'hui | C27: =TODAY() -> 45909
B28: Panne N° 1 - Début | C28: 45506
B29: Panne N° 1 - Fin | C29: 45509
B30: Temps Moyen de Réparation - panne N° 1 | D30: =C29-C28 -> 3 | E30: jours
B31: Panne N° 2 - Début
B32: Panne N° 2 - Fin
B33: Temps Moyen de Réparation - panne N° 2 | E33: jours
B34: Panne N° 3 - Début
B35: Panne N° 3 - Fin
B36: Temps Moyen de Réparation - panne N° 3 | E36: jours
